(0.000) 
            SELECT name, type FROM sqlite_master
            WHERE type in ('table', 'view') AND NOT name='sqlite_sequence'
            ORDER BY name; args=None
(0.003) SELECT "django_migrations"."app", "django_migrations"."name" FROM "django_migrations"; args=()
(0.001) 
            SELECT name, type FROM sqlite_master
            WHERE type in ('table', 'view') AND NOT name='sqlite_sequence'
            ORDER BY name; args=None
(0.004) SELECT "django_migrations"."app", "django_migrations"."name" FROM "django_migrations"; args=()
Exception while resolving variable 'name' in template 'unknown'.
Traceback (most recent call last):
  File "/home/tang/.local/share/virtualenvs/py3.6-3ezwSy6Y/lib/python3.6/site-packages/django/core/handlers/exception.py", line 34, in inner
    response = get_response(request)
  File "/home/tang/.local/share/virtualenvs/py3.6-3ezwSy6Y/lib/python3.6/site-packages/django/core/handlers/base.py", line 111, in _get_response
    resolver_match = resolver.resolve(request.path_info)
  File "/home/tang/.local/share/virtualenvs/py3.6-3ezwSy6Y/lib/python3.6/site-packages/django/urls/resolvers.py", line 520, in resolve
    raise Resolver404({'tried': tried, 'path': new_path})
django.urls.exceptions.Resolver404: {'tried': [[<URLResolver <URLPattern list> (admin:admin) 'admin/'>], [<URLResolver <module 'nima.urls' from '/home/tang/git-pkg/mypy/py3.6/django_proj/vcp/nima/urls.py'> (None:None) 'nima/'>]], 'path': ''}

During handling of the above exception, another exception occurred:

Traceback (most recent call last):
  File "/home/tang/.local/share/virtualenvs/py3.6-3ezwSy6Y/lib/python3.6/site-packages/django/template/base.py", line 829, in _resolve_lookup
    current = current[bit]
TypeError: 'URLResolver' object is not subscriptable

During handling of the above exception, another exception occurred:

Traceback (most recent call last):
  File "/home/tang/.local/share/virtualenvs/py3.6-3ezwSy6Y/lib/python3.6/site-packages/django/template/base.py", line 837, in _resolve_lookup
    current = getattr(current, bit)
AttributeError: 'URLResolver' object has no attribute 'name'

During handling of the above exception, another exception occurred:

Traceback (most recent call last):
  File "/home/tang/.local/share/virtualenvs/py3.6-3ezwSy6Y/lib/python3.6/site-packages/django/template/base.py", line 843, in _resolve_lookup
    current = current[int(bit)]
ValueError: invalid literal for int() with base 10: 'name'

During handling of the above exception, another exception occurred:

Traceback (most recent call last):
  File "/home/tang/.local/share/virtualenvs/py3.6-3ezwSy6Y/lib/python3.6/site-packages/django/template/base.py", line 850, in _resolve_lookup
    (bit, current))  # missing attribute
django.template.base.VariableDoesNotExist: Failed lookup for key [name] in <URLResolver <URLPattern list> (admin:admin) 'admin/'>
Exception while resolving variable 'name' in template 'unknown'.
Traceback (most recent call last):
  File "/home/tang/.local/share/virtualenvs/py3.6-3ezwSy6Y/lib/python3.6/site-packages/django/core/handlers/exception.py", line 34, in inner
    response = get_response(request)
  File "/home/tang/.local/share/virtualenvs/py3.6-3ezwSy6Y/lib/python3.6/site-packages/django/core/handlers/base.py", line 111, in _get_response
    resolver_match = resolver.resolve(request.path_info)
  File "/home/tang/.local/share/virtualenvs/py3.6-3ezwSy6Y/lib/python3.6/site-packages/django/urls/resolvers.py", line 520, in resolve
    raise Resolver404({'tried': tried, 'path': new_path})
django.urls.exceptions.Resolver404: {'tried': [[<URLResolver <URLPattern list> (admin:admin) 'admin/'>], [<URLResolver <module 'nima.urls' from '/home/tang/git-pkg/mypy/py3.6/django_proj/vcp/nima/urls.py'> (None:None) 'nima/'>]], 'path': ''}

During handling of the above exception, another exception occurred:

Traceback (most recent call last):
  File "/home/tang/.local/share/virtualenvs/py3.6-3ezwSy6Y/lib/python3.6/site-packages/django/template/base.py", line 829, in _resolve_lookup
    current = current[bit]
TypeError: 'URLResolver' object is not subscriptable

During handling of the above exception, another exception occurred:

Traceback (most recent call last):
  File "/home/tang/.local/share/virtualenvs/py3.6-3ezwSy6Y/lib/python3.6/site-packages/django/template/base.py", line 837, in _resolve_lookup
    current = getattr(current, bit)
AttributeError: 'URLResolver' object has no attribute 'name'

During handling of the above exception, another exception occurred:

Traceback (most recent call last):
  File "/home/tang/.local/share/virtualenvs/py3.6-3ezwSy6Y/lib/python3.6/site-packages/django/template/base.py", line 843, in _resolve_lookup
    current = current[int(bit)]
ValueError: invalid literal for int() with base 10: 'name'

During handling of the above exception, another exception occurred:

Traceback (most recent call last):
  File "/home/tang/.local/share/virtualenvs/py3.6-3ezwSy6Y/lib/python3.6/site-packages/django/template/base.py", line 850, in _resolve_lookup
    (bit, current))  # missing attribute
django.template.base.VariableDoesNotExist: Failed lookup for key [name] in <URLResolver <module 'nima.urls' from '/home/tang/git-pkg/mypy/py3.6/django_proj/vcp/nima/urls.py'> (None:None) 'nima/'>
Not Found: /
"GET / HTTP/1.1" 404 2029
"GET /nima HTTP/1.1" 301 0
access home
"GET /nima/ HTTP/1.1" 200 18
(0.000) 
            SELECT name, type FROM sqlite_master
            WHERE type in ('table', 'view') AND NOT name='sqlite_sequence'
            ORDER BY name; args=None
(0.000) SELECT "django_migrations"."app", "django_migrations"."name" FROM "django_migrations"; args=()
access home
"GET /nima HTTP/1.1" 200 18
Exception while resolving variable 'name' in template 'unknown'.
Traceback (most recent call last):
  File "/home/tang/.local/share/virtualenvs/py3.6-3ezwSy6Y/lib/python3.6/site-packages/django/core/handlers/exception.py", line 34, in inner
    response = get_response(request)
  File "/home/tang/.local/share/virtualenvs/py3.6-3ezwSy6Y/lib/python3.6/site-packages/django/core/handlers/base.py", line 111, in _get_response
    resolver_match = resolver.resolve(request.path_info)
  File "/home/tang/.local/share/virtualenvs/py3.6-3ezwSy6Y/lib/python3.6/site-packages/django/urls/resolvers.py", line 520, in resolve
    raise Resolver404({'tried': tried, 'path': new_path})
django.urls.exceptions.Resolver404: {'tried': [[<URLResolver <URLPattern list> (admin:admin) 'admin/'>], [<URLResolver <module 'nima.urls' from '/home/tang/git-pkg/mypy/py3.6/django_proj/vcp/nima/urls.py'> (None:None) 'nima'>, <URLPattern '' [name='home']>], [<URLResolver <module 'nima.urls' from '/home/tang/git-pkg/mypy/py3.6/django_proj/vcp/nima/urls.py'> (None:None) 'nima'>, <URLPattern 'hey'>]], 'path': 'nima/'}

During handling of the above exception, another exception occurred:

Traceback (most recent call last):
  File "/home/tang/.local/share/virtualenvs/py3.6-3ezwSy6Y/lib/python3.6/site-packages/django/template/base.py", line 829, in _resolve_lookup
    current = current[bit]
TypeError: 'URLResolver' object is not subscriptable

During handling of the above exception, another exception occurred:

Traceback (most recent call last):
  File "/home/tang/.local/share/virtualenvs/py3.6-3ezwSy6Y/lib/python3.6/site-packages/django/template/base.py", line 837, in _resolve_lookup
    current = getattr(current, bit)
AttributeError: 'URLResolver' object has no attribute 'name'

During handling of the above exception, another exception occurred:

Traceback (most recent call last):
  File "/home/tang/.local/share/virtualenvs/py3.6-3ezwSy6Y/lib/python3.6/site-packages/django/template/base.py", line 843, in _resolve_lookup
    current = current[int(bit)]
ValueError: invalid literal for int() with base 10: 'name'

During handling of the above exception, another exception occurred:

Traceback (most recent call last):
  File "/home/tang/.local/share/virtualenvs/py3.6-3ezwSy6Y/lib/python3.6/site-packages/django/template/base.py", line 850, in _resolve_lookup
    (bit, current))  # missing attribute
django.template.base.VariableDoesNotExist: Failed lookup for key [name] in <URLResolver <URLPattern list> (admin:admin) 'admin/'>
Not Found: /nima/
"GET /nima/ HTTP/1.1" 404 2275
access home
"GET /nima HTTP/1.1" 200 18
access home
"GET /nima HTTP/1.1" 200 18
Exception while resolving variable 'name' in template 'unknown'.
Traceback (most recent call last):
  File "/home/tang/.local/share/virtualenvs/py3.6-3ezwSy6Y/lib/python3.6/site-packages/django/core/handlers/exception.py", line 34, in inner
    response = get_response(request)
  File "/home/tang/.local/share/virtualenvs/py3.6-3ezwSy6Y/lib/python3.6/site-packages/django/core/handlers/base.py", line 111, in _get_response
    resolver_match = resolver.resolve(request.path_info)
  File "/home/tang/.local/share/virtualenvs/py3.6-3ezwSy6Y/lib/python3.6/site-packages/django/urls/resolvers.py", line 520, in resolve
    raise Resolver404({'tried': tried, 'path': new_path})
django.urls.exceptions.Resolver404: {'tried': [[<URLResolver <URLPattern list> (admin:admin) 'admin/'>], [<URLResolver <module 'nima.urls' from '/home/tang/git-pkg/mypy/py3.6/django_proj/vcp/nima/urls.py'> (None:None) 'nima'>]], 'path': 'favicon.ico'}

During handling of the above exception, another exception occurred:

Traceback (most recent call last):
  File "/home/tang/.local/share/virtualenvs/py3.6-3ezwSy6Y/lib/python3.6/site-packages/django/template/base.py", line 829, in _resolve_lookup
    current = current[bit]
TypeError: 'URLResolver' object is not subscriptable

During handling of the above exception, another exception occurred:

Traceback (most recent call last):
  File "/home/tang/.local/share/virtualenvs/py3.6-3ezwSy6Y/lib/python3.6/site-packages/django/template/base.py", line 837, in _resolve_lookup
    current = getattr(current, bit)
AttributeError: 'URLResolver' object has no attribute 'name'

During handling of the above exception, another exception occurred:

Traceback (most recent call last):
  File "/home/tang/.local/share/virtualenvs/py3.6-3ezwSy6Y/lib/python3.6/site-packages/django/template/base.py", line 843, in _resolve_lookup
    current = current[int(bit)]
ValueError: invalid literal for int() with base 10: 'name'

During handling of the above exception, another exception occurred:

Traceback (most recent call last):
  File "/home/tang/.local/share/virtualenvs/py3.6-3ezwSy6Y/lib/python3.6/site-packages/django/template/base.py", line 850, in _resolve_lookup
    (bit, current))  # missing attribute
django.template.base.VariableDoesNotExist: Failed lookup for key [name] in <URLResolver <URLPattern list> (admin:admin) 'admin/'>
Exception while resolving variable 'name' in template 'unknown'.
Traceback (most recent call last):
  File "/home/tang/.local/share/virtualenvs/py3.6-3ezwSy6Y/lib/python3.6/site-packages/django/core/handlers/exception.py", line 34, in inner
    response = get_response(request)
  File "/home/tang/.local/share/virtualenvs/py3.6-3ezwSy6Y/lib/python3.6/site-packages/django/core/handlers/base.py", line 111, in _get_response
    resolver_match = resolver.resolve(request.path_info)
  File "/home/tang/.local/share/virtualenvs/py3.6-3ezwSy6Y/lib/python3.6/site-packages/django/urls/resolvers.py", line 520, in resolve
    raise Resolver404({'tried': tried, 'path': new_path})
django.urls.exceptions.Resolver404: {'tried': [[<URLResolver <URLPattern list> (admin:admin) 'admin/'>], [<URLResolver <module 'nima.urls' from '/home/tang/git-pkg/mypy/py3.6/django_proj/vcp/nima/urls.py'> (None:None) 'nima'>]], 'path': 'favicon.ico'}

During handling of the above exception, another exception occurred:

Traceback (most recent call last):
  File "/home/tang/.local/share/virtualenvs/py3.6-3ezwSy6Y/lib/python3.6/site-packages/django/template/base.py", line 829, in _resolve_lookup
    current = current[bit]
TypeError: 'URLResolver' object is not subscriptable

During handling of the above exception, another exception occurred:

Traceback (most recent call last):
  File "/home/tang/.local/share/virtualenvs/py3.6-3ezwSy6Y/lib/python3.6/site-packages/django/template/base.py", line 837, in _resolve_lookup
    current = getattr(current, bit)
AttributeError: 'URLResolver' object has no attribute 'name'

During handling of the above exception, another exception occurred:

Traceback (most recent call last):
  File "/home/tang/.local/share/virtualenvs/py3.6-3ezwSy6Y/lib/python3.6/site-packages/django/template/base.py", line 843, in _resolve_lookup
    current = current[int(bit)]
ValueError: invalid literal for int() with base 10: 'name'

During handling of the above exception, another exception occurred:

Traceback (most recent call last):
  File "/home/tang/.local/share/virtualenvs/py3.6-3ezwSy6Y/lib/python3.6/site-packages/django/template/base.py", line 850, in _resolve_lookup
    (bit, current))  # missing attribute
django.template.base.VariableDoesNotExist: Failed lookup for key [name] in <URLResolver <module 'nima.urls' from '/home/tang/git-pkg/mypy/py3.6/django_proj/vcp/nima/urls.py'> (None:None) 'nima'>
Not Found: /favicon.ico
"GET /favicon.ico HTTP/1.1" 404 2079
access home
"GET /nima HTTP/1.1" 200 18
access home
"GET /nima HTTP/1.1" 200 18
access home
"GET /nima HTTP/1.1" 200 18
access home
"GET /nima HTTP/1.1" 200 18
access home
"GET /nima HTTP/1.1" 200 18
access home
"OPTIONS /nima HTTP/1.1" 200 18
access home
"OPTIONS /nima HTTP/1.1" 200 18
access home
"GET /nima HTTP/1.1" 200 18
(0.001) 
            SELECT name, type FROM sqlite_master
            WHERE type in ('table', 'view') AND NOT name='sqlite_sequence'
            ORDER BY name; args=None
(0.000) SELECT "django_migrations"."app", "django_migrations"."name" FROM "django_migrations"; args=()
access home
"GET /nima HTTP/1.1" 200 18
(0.000) 
            SELECT name, type FROM sqlite_master
            WHERE type in ('table', 'view') AND NOT name='sqlite_sequence'
            ORDER BY name; args=None
(0.000) SELECT "django_migrations"."app", "django_migrations"."name" FROM "django_migrations"; args=()
